Workbook
Name Slicer_Entity: #N/A
Name Slicer_Perporting_period: #N/A
Name Slicer_Year: #N/A
Name Slicer_Year1: #N/A

Sheet Dashboard

Sheet NKE INCOME STATEMENT ANNUAL RAW
A1: Period Ending: | B1: LTM (Last Twelve Months) | C1: 2025 05-31 | D1: 2024 05-31 | E1: 2023 05-31 | F1: 2022 05-31 | G1: 2021 05-31 | H1: 2020 05-31
A2: Report Filing | B2: 2025-12-30 | C2: 2025-07-17 | D2: 2024-07-25 | E2: 2023-07-20 | F2: 2022-07-21 | G2: 2021-07-20 | H2: 2020-07-24
A3: Revenue | B3: 46,513 | C3: 46,309 | D3: 51,362 | E3: 51,217 | F3: 46,710 | G3: 44,538 | H3: 37,403
A4: Cost of Revenue | B4: 27,381 | C4: 26,519 | D4: 28,475 | E4: 28,925 | F4: 25,231 | G4: 24,576 | H4: 21,162
A5: Gross Profit | B5: 19,132 | C5: 19,790 | D5: 22,887 | E5: 22,292 | F5: 21,479 | G5: 19,962 | H5: 16,241
A6: Operating Expenses | B6: 16,090 | C6: 16,088 | D6: 16,576 | E6: 16,377 | F6: 14,804 | G6: 13,025 | H6: 13,126
A7: Research & Development | B7: 0 | C7: 0 | D7: 0 | E7: 0 | F7: 0 | G7: 0 | H7: 0
A8: Selling, General and Administrative | B8: 16,090 | C8: 16,088 | D8: 16,576 | E8: 16,377 | F8: 14,804 | G8: 13,025 | H8: 13,126
A9: Other Operating Expenses | B9: 0 | C9: 0 | D9: 0 | E9: 0 | F9: 0 | G9: 0 | H9: 0
A10: Operating Income | B10: 3,042 | C10: 3,702 | D10: 6,311 | E10: 5,915 | F10: 6,675 | G10: 6,937 | H10: 3,115
A11: Net Non-Operating Interest | B11: 57 | C11: 115 | D11: 169 | E11: 14 | F11: -198 | G11: -255 | H11: -82
A12: Interest Income | B12: 353 | C12: 404 | D12: 430 | E12: 297 | F12: 94 | G12: 34 | H12: 62
... A24: Diluted Weighted Average Shares Outstanding | B24: 1,480 | C24: 1,488 | D24: 1,530 | E24: 1,570 | F24: 1,611 | G24: 1,609 | H24: 1,592
A26: Period Ending: | B26: LTM (Last Twelve Months) | C26: 2025 05-31 | D26: 2024 05-31 | E26: 2023 05-31 | F26: 2022 05-31 | G26: 2021 05-31
A27: Report Filing | B27: 2025-12-30 | C27: 2025-07-17 | D27: 2024-07-25 | E27: 2023-07-20 | F27: 2022-07-21 | G27: 2021-07-20
A28: Revenue | B28: 46.513 | C28: 46.309 | D28: 51.362 | E28: 51.217 | F28: 46.71 | G28: 44.538
A29: Cost of Revenue | B29: 27.381 | C29: 26.519 | D29: 28.475 | E29: 28.925 | F29: 25.231 | G29: 24.576
A30: Gross Profit | B30: 19.132 | C30: 19.79 | D30: 22.887 | E30: 22.292 | F30: 21.479 | G30: 19.962
A31: Operating Expenses | B31: 16.09 | C31: 16.088 | D31: 16.576 | E31: 16.377 | F31: 14.804 | G31: 13.025
A32: Research & Development | B32: 0 | C32: 0 | D32: 0 | E32: 0 | F32: 0 | G32: 0
A33: Selling, General and Administrative | B33: 16.09 | C33: 16.088 | D33: 16.576 | E33: 16.377 | F33: 14.804 | G33: 13.025
A34: Other Operating Expenses | B34: 0 | C34: 0 | D34: 0 | E34: 0 | F34: 0 | G34: 0
A35: Operating Income | B35: 3.042 | C35: 3.702 | D35: 6.311 | E35: 5.915 | F35: 6.675 | G35: 6.937
A36: Net Non-Operating Interest | B36: 57 | C36: 115 | D36: 169 | E36: 14 | F36: -198 | G36: -255
A37: Interest Income | B37: 353 | C37: 404 | D37: 430 | E37: 297 | F37: 94 | G37: 34
A38: Interest Expense | B38: 296 | C38: 289 | D38: 261 | E38: 283 | F38: 292 | G38: 289
A39: Equity & Other Income/(Expense) | B39: -16 | C39: 68 | D39: 220 | E39: 272 | F39: 174 | G39: -21
... A45: EBITDA | B45: 3.671 | C45: 4.51 | D45: 7.155 | E45: 6.774 | F45: 7.515 | G45: 7.734
A46: Earnings Per Share (EPS) | B46: 1.71 | C46: 2.17 | D46: 3.76 | E46: 3.27 | F46: 3.83 | G46: 3.64
A47: Diluted Earnings Per Share | B47: 1.71 | C47: 2.16 | D47: 3.73 | E47: 3.23 | F47: 3.75 | G47: 3.56
A48: Weighted Average Shares Outstanding | B48: 1.478 | C48: 1.485 | D48: 1.518 | E48: 1.552 | F48: 1.579 | G48: 1.573
A49: Diluted Weighted Average Shares Outstanding | B49: 1.48 | C49: 1.488 | D49: 1.53 | E49: 1.57 | F49: 1.611 | G49: 1.609
A51: gross margin | C51: =C30/C28 -> 0.42734674 | D51: =D30/D28 -> 0.44560181 | E51: =E30/E28 -> 0.43524611 | F51: =F30/F28 -> 0.45983729 | G51: =G30/G28 -> 0.44820154
B54: 2020 05-31 | D54: 37,403 | E54: 21,162 | F54: 16,241 | G54: 13,126 | H54: 0 | I54: 13,126 | J54: 0 | K54: 3,115 | L54: -82 | M54: 62 | N54: 144 | O54: -146 | P54: 2,887 | Q54: 348 | R54: 0 | S54: 2,539 | T54: 1,119 | U54: 4,234 | V54: 1.63 | W54: 1.6 | X54: 1,559 | Y54: 1,592

Sheet NKE BALANCE SHEET ANNUAL RAW
A1: Reporting Period Ending | B1: 2025 05-31 | C1: 2024 05-31 | D1: 2023 05-31 | E1: 2022 05-31 | F1: 2021 05-31 | G1: 2020 05-31
A2: Report Filing: | B2: 2025-07-17 | C2: 2024-07-25 | D2: 2023-07-20 | E2: 2022-07-21 | F2: 2021-07-20 | G2: 2020-07-24
A3: Total Current Assets | B3: 23,362 | C3: 25,382 | D3: 25,202 | E3: 28,213 | F3: 26,291 | G3: 20,556
A4: Cash and Short Term Investments | B4: 9,151 | C4: 11,582 | D4: 10,675 | E4: 12,997 | F4: 13,476 | G4: 8,787
A5: Cash & Equivalents | B5: 7,464 | C5: 9,860 | D5: 7,441 | E5: 8,574 | F5: 9,889 | G5: 8,348
A6: Short Term Investments | B6: 1,687 | C6: 1,722 | D6: 3,234 | E6: 4,423 | F6: 3,587 | G6: 439
A7: Receivables | B7: 4,717 | C7: 4,427 | D7: 4,131 | E7: 4,667 | F7: 4,463 | G7: 2,749
A8: Inventory | B8: 7,489 | C8: 7,519 | D8: 8,454 | E8: 8,420 | F8: 6,854 | G8: 7,367
A9: Other Current Assets | B9: 2,005 | C9: 1,854 | D9: 1,942 | E9: 2,129 | F9: 1,498 | G9: 1,653
A10: Total Assets | B10: 36,579 | C10: 38,110 | D10: 37,531 | E10: 40,321 | F10: 37,740 | G10: 31,342
A11: Total Non-Current Assets | B11: 13,217 | C11: 12,728 | D11: 12,329 | E11: 12,108 | F11: 11,449 | G11: 10,786
A12: Property, Plant and Equipment | B12: 7,540 | C12: 7,718 | D12: 8,004 | E12: 7,717 | F12: 8,017 | G12: 7,963
... A44: Net Debt | B44: 3,554 | C44: 2,092 | D44: 4,703 | E44: 4,053 | F44: 2,924 | G44: 4,667

Sheet NKE CASHFLOW STATEMENTS ANNUAL
A1: Period Ending: | B1: LTM (Last Twelve Months) | C1: 2025 05-31 | D1: 2024 05-31 | E1: 2023 05-31 | F1: 2022 05-31 | G1: 2021 05-31
A2: Report Filing: | B2: 2025-12-30 | C2: 2025-07-17 | D2: 2024-07-25 | E2: 2023-07-20 | F2: 2022-07-21 | G2: 2021-07-20
A3: Net Income/Starting Line | B3: 2,524 | C3: 3,219 | D3: 5,700 | E3: 5,070 | F3: 6,046 | G3: 5,727
A4: Cash From Operating Activities | B4: 3,056 | C4: 3,698 | D4: 7,429 | E4: 5,841 | F4: 5,188 | G4: 6,657
A5: Depreciation and Amortization | B5: 775 | C5: 775 | D5: 844 | E5: 859 | F5: 840 | G5: 797
A6: Deferred Income Tax | B6: -168 | C6: -288 | D6: -497 | E6: -117 | F6: -650 | G6: -385
A7: Stock Based Compensation | B7: 695 | C7: 709 | D7: 804 | E7: 755 | F7: 638 | G7: 611
A8: Other Non-Cash Items | B8: -1,364 | C8: 70 | D8: -138 | E8: -213 | F8: -26 | G8: -138
A9: Changes in Working Capital | B9: 594 | C9: -787 | D9: 716 | E9: -513 | F9: -1,660 | G9: 45
A10: Accounts Receivable | B10: -335 | C10: -257 | D10: -329 | E10: 489 | F10: -504 | G10: -1,606
A11: Inventory | B11: 410 | C11: 120 | D11: 908 | E11: -133 | F11: -1,676 | G11: 507
A12: Accounts Payable | B12: -671 | C12: -426 | D12: 397 | E12: -225 | F12: 1,365 | G12: 1,326
... A33: Capital Expenditure | B33: -581 | C33: -430 | D33: -812 | E33: -969 | F33: -758 | G33: -695

Sheet NKE DIVIDENDS
A1: Period Ending: | B1: LTM | C1: 2025 | D1: 2024 | E1: 2023 | F1: 2022 | G1: 2021 | H1: 2020
A2: Dividend per Share | B2: 1.61 | C2: 1.61 | D2: 1.51 | E2: 1.39 | F2: 1.25 | G2: 1.13 | H2: 1.01
A3: Reference Market Share Price | B3: 64.41 | C3: 63.71 | D3: 75.67 | E3: 108.6 | F3: 117 | G3: 166.7 | H3: 141.5
A4: Dividend Yield | B4: 2.5% | C4: 2.53% | D4: 2% | E4: 1.28% | F4: 1.07% | G4: 0.678% | H4: 0.714%
A5: Earnings Per Share | B5: 1.71 | C5: 2.17 | D5: 3.76 | E5: 3.27 | F5: 3.83 | G5: 3.64 | H5: 1.63
A6: Payout Ratio | B6: 94.15% | C6: 74.19% | D6: 40.16% | E6: 42.51% | F6: 32.64% | G6: 31.04% | H6: 61.96%
A8: Period Ending: | B8: Dividend per Share | C8: Reference Market Share Price | D8: Dividend Yield | E8: Earnings Per Share | F8: Payout Ratio
A9: 2025 | B9: 1.61 | C9: 63.71 | D9: 2.53% | E9: 2.17 | F9: 74.19%
A10: 2024 | B10: 1.51 | C10: 75.67 | D10: 2% | E10: 3.76 | F10: 40.16%
A11: 2023 | B11: 1.39 | C11: 108.6 | D11: 1.28% | E11: 3.27 | F11: 42.51%
A12: 2022 | B12: 1.25 | C12: 117 | D12: 1.07% | E12: 3.83 | F12: 32.64%
A13: 2021 | B13: 1.13 | C13: 166.7 | D13: 0.678% | E13: 3.64 | F13: 31.04%
A14: 2020 | B14: 1.01 | C14: 141.5 | D14: 0.714% | E14: 1.63 | F14: 61.96%
G16: Helper column
G17: =CODE(MID(B9,1,1)) -> 49 | H17: =LEN(B9) -> 4

Sheet Insights Pivot
A1: Year | B1: 2023
A3: Row Labels | B3: Sum of Amount
A4: Earnings Bridge Driver | B4: 4.507
A5: Gross margin percentage | B5: 0.43524611
A6: Net Income Margin | B6: -0.16142904
A7: Operating expense ratio | B7: 0.31975711
A8: Revenue Growth | B8: 0.096488975
A9: Grand Total | B9: 5.1970632

Sheet IS ANALYSIS
A1: Reporting Period Ending 31 May: | B1: Revenue | C1: Cost of Revenue | D1: Gross Profit | E1: Operating Expenses | F1: Research & Development | G1: Selling, General and Administrative | H1: Other Operating Expenses | I1: Operating Income | J1: Net Non-Operating Interest | K1: Interest Income | L1: Interest Expense | M1: Equity & Other Income/(Expense) | N1: Income Before Tax | O1: Income Tax Expense | P1: Income Attributable to Non-Controlling Interest | Q1: Net Income | R1: Depreciation and Amortization | S1: EBITDA | T1: Earnings Per Share (EPS) | U1: Diluted Earnings Per Share | V1: Weighted Average Shares Outstanding | W1: Diluted Weighted Average Shares Outstanding | X1: Gross Margin | Y1: Operating Margin | Z1: Net Profit Margin | AA1: Average Total assets | AB1: ROA | AC1: Average equity | AD1: ROE
A2: 2025 | B2: 46.309 | C2: 26.519 | D2: 19.79 | E2: 16.088 | F2: 0 | G2: 16.088 | H2: 0 | I2: 3.702 | J2: 115 | K2: 404 | L2: 289 | M2: 68 | N2: 3.885 | O2: 666 | P2: 0 | Q2: 3.219 | R2: 808 | S2: 4.51 | T2: 2.17 | U2: 2.16 | V2: 1.485 | W2: 1.488 | X2: =Table2[[#This Row],[Gross Profit]]/Table2[[#This Row],[Revenue]] -> 0.42734674 | Y2: =Table2[[#This Row],[Operating Income]]/Table2[[#This Row],[Revenue]] -> 0.079941264 | Z2: =Table2[[#This Row],[Net Income]]/Table2[[#This Row],[Revenue]] -> 0.069511326 | AA2: =(Table1[[#This Row],[Total Assets]]+'BS ANALYSIS'!I3)/2 -> 37.3445 | AB2: =Table2[[#This Row],[Net Income]]/Table2[[#This Row],[Average Total assets]] -> 0.086197432 | AC2: =(Table1[[#This Row],[Total Equity]]+'BS ANALYSIS'!AE3)/2 -> 13.8215 | AD2: =Table2[[#This Row],[Net Income]]/Table2[[#This Row],[Average equity]] -> 0.23289802
A3: 2024 | B3: 51.362 | C3: 28.475 | D3: 22.887 | E3: 16.576 | F3: 0 | G3: 16.576 | H3: 0 | I3: 6.311 | J3: 169 | K3: 430 | L3: 261 | M3: 220 | N3: 6.7 | O3: 1 | P3: 0 | Q3: 5.7 | R3: 844 | S3: 7.155 | T3: 3.76 | U3: 3.73 | V3: 1.518 | W3: 1.53 | X3: =Table2[[#This Row],[Gross Profit]]/Table2[[#This Row],[Revenue]] -> 0.44560181 | Y3: =Table2[[#This Row],[Operating Income]]/Table2[[#This Row],[Revenue]] -> 0.12287294 | Z3: =Table2[[#This Row],[Net Income]]/Table2[[#This Row],[Revenue]] -> 0.11097699 | AA3: =(Table1[[#This Row],[Total Assets]]+'BS ANALYSIS'!I4)/2 -> 37.8205 | AB3: =Table2[[#This Row],[Net Income]]/Table2[[#This Row],[Average Total assets]] -> 0.15071192 | AC3: =(Table1[[#This Row],[Total Equity]]+'BS ANALYSIS'!AE4)/2 -> 14.217 | AD3: =Table2[[#This Row],[Net Income]]/Table2[[#This Row],[Average equity]] -> 0.40092847
A4: 2023 | B4: 51.217 | C4: 28.925 | D4: 22.292 | E4: 16.377 | F4: 0 | G4: 16.377 | H4: 0 | I4: 5.915 | J4: 14 | K4: 297 | L4: 283 | M4: 272 | N4: 6.201 | O4: 1.131 | P4: 0 | Q4: 5.07 | R4: 859 | S4: 6.774 | T4: 3.27 | U4: 3.23 | V4: 1.552 | W4: 1.57 | X4: =Table2[[#This Row],[Gross Profit]]/Table2[[#This Row],[Revenue]] -> 0.43524611 | Y4: =Table2[[#This Row],[Operating Income]]/Table2[[#This Row],[Revenue]] -> 0.115489 | Z4: =Table2[[#This Row],[Net Income]]/Table2[[#This Row],[Revenue]] -> 0.09899057 | AA4: =(Table1[[#This Row],[Total Assets]]+'BS ANALYSIS'!I5)/2 -> 38.926 | AB4: =Table2[[#This Row],[Net Income]]/Table2[[#This Row],[Average Total assets]] -> 0.13024714 | AC4: =(Table1[[#This Row],[Total Equity]]+'BS ANALYSIS'!AE5)/2 -> 14.6425 | AD4: =Table2[[#This Row],[Net Income]]/Table2[[#This Row],[Average equity]] -> 0.34625235
A5: 2022 | B5: 46.71 | C5: 25.231 | D5: 21.479 | E5: 14.804 | F5: 0 | G5: 14.804 | H5: 0 | I5: 6.675 | J5: -198 | K5: 94 | L5: 292 | M5: 174 | N5: 6.651 | O5: 605 | P5: 0 | Q5: 6.046 | R5: 840 | S5: 7.515 | T5: 3.83 | U5: 3.75 | V5: 1.579 | W5: 1.611 | X5: =Table2[[#This Row],[Gross Profit]]/Table2[[#This Row],[Revenue]] -> 0.45983729 | Y5: =Table2[[#This Row],[Operating Income]]/Table2[[#This Row],[Revenue]] -> 0.14290302 | Z5: =Table2[[#This Row],[Net Income]]/Table2[[#This Row],[Revenue]] -> 0.12943695 | AA5: =(Table1[[#This Row],[Total Assets]]+'BS ANALYSIS'!I6)/2 -> 39.0305 | AB5: =Table2[[#This Row],[Net Income]]/Table2[[#This Row],[Average Total assets]] -> 0.1549045 | AC5: =(Table1[[#This Row],[Total Equity]]+'BS ANALYSIS'!AE6)/2 -> 14.024 | AD5: =Table2[[#This Row],[Net Income]]/Table2[[#This Row],[Average equity]] -> 0.43111808
A6: 2021 | B6: 44.538 | C6: 24.576 | D6: 19.962 | E6: 13.025 | F6: 0 | G6: 13.025 | H6: 0 | I6: 6.937 | J6: -255 | K6: 34 | L6: 289 | M6: -21 | N6: 6.661 | O6: 934 | P6: 0 | Q6: 5.727 | R6: 797 | S6: 7.734 | T6: 3.64 | U6: 3.56 | V6: 1.573 | W6: 1.609 | X6: =Table2[[#This Row],[Gross Profit]]/Table2[[#This Row],[Revenue]] -> 0.44820154 | Y6: =Table2[[#This Row],[Operating Income]]/Table2[[#This Row],[Revenue]] -> 0.15575464 | Z6: =Table2[[#This Row],[Net Income]]/Table2[[#This Row],[Revenue]] -> 0.12858682 | AA6: =(Table1[[#This Row],[Total Assets]]+'BS ANALYSIS'!I7)/2 -> 34.541 | AB6: =Table2[[#This Row],[Net Income]]/Table2[[#This Row],[Average Total assets]] -> 0.16580296 | AC6: =(Table1[[#This Row],[Total Equity]]+'BS ANALYSIS'!AE7)/2 -> 10.411 | AD6: =Table2[[#This Row],[Net Income]]/Table2[[#This Row],[Average equity]] -> 0.55009125
A7: 2020 | B7: 37.403 | C7: 21.162 | D7: 16.241 | E7: 13.126 | F7: 0 | G7: 13.126 | H7: 0 | I7: 3.115 | J7: -82 | K7: 62 | L7: 144 | M7: -146 | N7: 2.887 | O7: 348 | P7: 0 | Q7: 2.539 | R7: 1.119 | S7: 4.234 | T7: 1.63 | U7: 1.6 | V7: 1.559 | W7: 1.592 | X7: =Table2[[#This Row],[Gross Profit]]/Table2[[#This Row],[Revenue]] -> 0.43421651 | Y7: =Table2[[#This Row],[Operating Income]]/Table2[[#This Row],[Revenue]] -> 0.08328209 | Z7: =Table2[[#This Row],[Net Income]]/Table2[[#This Row],[Revenue]] -> 0.067882255 | AA7: =(Table1[[#This Row],[Total Assets]]+'BS ANALYSIS'!I8)/2 -> 15.671 | AB7: =Table2[[#This Row],[Net Income]]/Table2[[#This Row],[Average Total assets]] -> 0.16201902 | AC7: =(Table1[[#This Row],[Total Equity]]+'BS ANALYSIS'!AE8)/2 -> 4.0275 | AD7: =Table2[[#This Row],[Net Income]]/Table2[[#This Row],[Average equity]] -> 0.63041589

Sheet VARIANCE ANALYSIS
A1: Reporting Period Ending 31 May: | B1: Revenue | C1: YoY ▲ | D1: YoY % | E1: Cost of Sales | F1: YoY ▲3 | G1: YoY %2 | H1: Gross Profit | I1: YoY ▲2 | J1: YoY %3 | K1: Operating Income | L1: YoY ▲4 | M1: YoY %5 | N1: Net Income | O1: YoY ▲5 | P1: YoY %4
A2: =Table2[[#This Row],[Reporting Period Ending 31 May:]] -> 2025 | B2: =Table2[[#This Row],[Revenue]] -> 46.309 | C2: =(Table2[[#This Row],[Revenue]]-'IS ANALYSIS'!B3) -> -5.053 | D2: =(Table2[[#This Row],[Revenue]]-'IS ANALYSIS'!B3)/'IS ANALYSIS'!B3 -> -0.098380125 | E2: =Table2[[#This Row],[Cost of Revenue]] -> 26.519 | F2: =Table2[[#This Row],[Cost of Revenue]]-'IS ANALYSIS'!C3 -> -1.956 | G2: =(Table2[[#This Row],[Cost of Revenue]]-'IS ANALYSIS'!C3)/'IS ANALYSIS'!C3 -> -0.068691835 | H2: =Table2[[#This Row],[Gross Profit]] -> 19.79 | I2: =Table2[[#This Row],[Gross Profit]]-'IS ANALYSIS'!D3 -> -3.097 | J2: =(Table2[[#This Row],[Gross Profit]]-'IS ANALYSIS'!D3)/'IS ANALYSIS'!D3 -> -0.13531699 | K2: =Table2[[#This Row],[Operating Income]] -> 3.702 | L2: =Table2[[#This Row],[Operating Income]]-'IS ANALYSIS'!I3 -> -2.609 | M2: =(Table2[[#This Row],[Operating Income]]-'IS ANALYSIS'!I3)/'IS ANALYSIS'!I3 -> -0.41340517 | N2: =Table2[[#This Row],[Net Income]] -> 3.219 | O2: =Table2[[#This Row],[Net Income]]-'IS ANALYSIS'!Q3 -> -2.481 | P2: =(Table2[[#This Row],[Net Income]]-'IS ANALYSIS'!Q3)/'IS ANALYSIS'!Q3 -> -0.43526316
A3: =Table2[[#This Row],[Reporting Period Ending 31 May:]] -> 2024 | B3: =Table2[[#This Row],[Revenue]] -> 51.362 | C3: =(Table2[[#This Row],[Revenue]]-'IS ANALYSIS'!B4) -> 0.145 | D3: =(Table2[[#This Row],[Revenue]]-'IS ANALYSIS'!B4)/'IS ANALYSIS'!B4 -> 0.0028310912 | E3: =Table2[[#This Row],[Cost of Revenue]] -> 28.475 | F3: =Table2[[#This Row],[Cost of Revenue]]-'IS ANALYSIS'!C4 -> -0.45 | G3: =(Table2[[#This Row],[Cost of Revenue]]-'IS ANALYSIS'!C4)/'IS ANALYSIS'!C4 -> -0.015557476 | H3: =Table2[[#This Row],[Gross Profit]] -> 22.887 | I3: =Table2[[#This Row],[Gross Profit]]-'IS ANALYSIS'!D4 -> 0.595 | J3: =(Table2[[#This Row],[Gross Profit]]-'IS ANALYSIS'!D4)/'IS ANALYSIS'!D4 -> 0.02669119 | K3: =Table2[[#This Row],[Operating Income]] -> 6.311 | L3: =Table2[[#This Row],[Operating Income]]-'IS ANALYSIS'!I4 -> 0.396 | M3: =(Table2[[#This Row],[Operating Income]]-'IS ANALYSIS'!I4)/'IS ANALYSIS'!I4 -> 0.066948436 | N3: =Table2[[#This Row],[Net Income]] -> 5.7 | O3: =Table2[[#This Row],[Net Income]]-'IS ANALYSIS'!Q4 -> 0.63 | P3: =(Table2[[#This Row],[Net Income]]-'IS ANALYSIS'!Q4)/'IS ANALYSIS'!Q4 -> 0.12426036
A4: =Table2[[#This Row],[Reporting Period Ending 31 May:]] -> 2023 | B4: =Table2[[#This Row],[Revenue]] -> 51.217 | C4: =(Table2[[#This Row],[Revenue]]-'IS ANALYSIS'!B5) -> 4.507 | D4: =(Table2[[#This Row],[Revenue]]-'IS ANALYSIS'!B5)/'IS ANALYSIS'!B5 -> 0.096488975 | E4: =Table2[[#This Row],[Cost of Revenue]] -> 28.925 | F4: =Table2[[#This Row],[Cost of Revenue]]-'IS ANALYSIS'!C5 -> 3.694 | G4: =(Table2[[#This Row],[Cost of Revenue]]-'IS ANALYSIS'!C5)/'IS ANALYSIS'!C5 -> 0.1464072 | H4: =Table2[[#This Row],[Gross Profit]] -> 22.292 | I4: =Table2[[#This Row],[Gross Profit]]-'IS ANALYSIS'!D5 -> 0.813 | J4: =(Table2[[#This Row],[Gross Profit]]-'IS ANALYSIS'!D5)/'IS ANALYSIS'!D5 -> 0.037850924 | K4: =Table2[[#This Row],[Operating Income]] -> 5.915 | L4: =Table2[[#This Row],[Operating Income]]-'IS ANALYSIS'!I5 -> -0.76 | M4: =(Table2[[#This Row],[Operating Income]]-'IS ANALYSIS'!I5)/'IS ANALYSIS'!I5 -> -0.11385768 | N4: =Table2[[#This Row],[Net Income]] -> 5.07 | O4: =Table2[[#This Row],[Net Income]]-'IS ANALYSIS'!Q5 -> -0.976 | P4: =(Table2[[#This Row],[Net Income]]-'IS ANALYSIS'!Q5)/'IS ANALYSIS'!Q5 -> -0.16142904
A5: =Table2[[#This Row],[Reporting Period Ending 31 May:]] -> 2022 | B5: =Table2[[#This Row],[Revenue]] -> 46.71 | C5: =(Table2[[#This Row],[Revenue]]-'IS ANALYSIS'!B6) -> 2.172 | D5: =(Table2[[#This Row],[Revenue]]-'IS ANALYSIS'!B6)/'IS ANALYSIS'!B6 -> 0.048767345 | E5: =Table2[[#This Row],[Cost of Revenue]] -> 25.231 | F5: =Table2[[#This Row],[Cost of Revenue]]-'IS ANALYSIS'!C6 -> 0.655 | G5: =(Table2[[#This Row],[Cost of Revenue]]-'IS ANALYSIS'!C6)/'IS ANALYSIS'!C6 -> 0.026652018 | H5: =Table2[[#This Row],[Gross Profit]] -> 21.479 | I5: =Table2[[#This Row],[Gross Profit]]-'IS ANALYSIS'!D6 -> 1.517 | J5: =(Table2[[#This Row],[Gross Profit]]-'IS ANALYSIS'!D6)/'IS ANALYSIS'!D6 -> 0.075994389 | K5: =Table2[[#This Row],[Operating Income]] -> 6.675 | L5: =Table2[[#This Row],[Operating Income]]-'IS ANALYSIS'!I6 -> -0.262 | M5: =(Table2[[#This Row],[Operating Income]]-'IS ANALYSIS'!I6)/'IS ANALYSIS'!I6 -> -0.037768488 | N5: =Table2[[#This Row],[Net Income]] -> 6.046 | O5: =Table2[[#This Row],[Net Income]]-'IS ANALYSIS'!Q6 -> 0.319 | P5: =(Table2[[#This Row],[Net Income]]-'IS ANALYSIS'!Q6)/'IS ANALYSIS'!Q6 -> 0.055701065
A6: =Table2[[#This Row],[Reporting Period Ending 31 May:]] -> 2021 | B6: =Table2[[#This Row],[Revenue]] -> 44.538 | C6: =(Table2[[#This Row],[Revenue]]-'IS ANALYSIS'!B7) -> 7.135 | D6: =(Table2[[#This Row],[Revenue]]-'IS ANALYSIS'!B7)/'IS ANALYSIS'!B7 -> 0.1907601 | E6: =Table2[[#This Row],[Cost of Revenue]] -> 24.576 | F6: =Table2[[#This Row],[Cost of Revenue]]-'IS ANALYSIS'!C7 -> 3.414 | G6: =(Table2[[#This Row],[Cost of Revenue]]-'IS ANALYSIS'!C7)/'IS ANALYSIS'!C7 -> 0.16132691 | H6: =Table2[[#This Row],[Gross Profit]] -> 19.962 | I6: =Table2[[#This Row],[Gross Profit]]-'IS ANALYSIS'!D7 -> 3.721 | J6: =(Table2[[#This Row],[Gross Profit]]-'IS ANALYSIS'!D7)/'IS ANALYSIS'!D7 -> 0.22911151 | K6: =Table2[[#This Row],[Operating Income]] -> 6.937 | L6: =Table2[[#This Row],[Operating Income]]-'IS ANALYSIS'!I7 -> 3.822 | M6: =(Table2[[#This Row],[Operating Income]]-'IS ANALYSIS'!I7)/'IS ANALYSIS'!I7 -> 1.2269663 | N6: =Table2[[#This Row],[Net Income]] -> 5.727 | O6: =Table2[[#This Row],[Net Income]]-'IS ANALYSIS'!Q7 -> 3.188 | P6: =(Table2[[#This Row],[Net Income]]-'IS ANALYSIS'!Q7)/'IS ANALYSIS'!Q7 -> 1.2556124
A7: =Table2[[#This Row],[Reporting Period Ending 31 May:]] -> 2020 | B7: =Table2[[#This Row],[Revenue]] -> 37.403 | C7: =(Table2[[#This Row],[Revenue]]-'IS ANALYSIS'!B8) -> 37.403 | D7: =(Table2[[#This Row],[Revenue]]-'IS ANALYSIS'!B8)/'IS ANALYSIS'!B8 -> #DIV/0! | E7: =Table2[[#This Row],[Cost of Revenue]] -> 21.162 | F7: =Table2[[#This Row],[Cost of Revenue]]-'IS ANALYSIS'!C8 -> 21.162 | G7: =(Table2[[#This Row],[Cost of Revenue]]-'IS ANALYSIS'!C8)/'IS ANALYSIS'!C8 -> #DIV/0! | H7: =Table2[[#This Row],[Gross Profit]] -> 16.241 | I7: =Table2[[#This Row],[Gross Profit]]-'IS ANALYSIS'!D8 -> 16.241 | J7: =(Table2[[#This Row],[Gross Profit]]-'IS ANALYSIS'!D8)/'IS ANALYSIS'!D8 -> #DIV/0! | K7: =Table2[[#This Row],[Operating Income]] -> 3.115 | L7: =Table2[[#This Row],[Operating Income]]-'IS ANALYSIS'!I8 -> 3.115 | M7: =(Table2[[#This Row],[Operating Income]]-'IS ANALYSIS'!I8)/'IS ANALYSIS'!I8 -> #DIV/0! | N7: =Table2[[#This Row],[Net Income]] -> 2.539 | O7: =Table2[[#This Row],[Net Income]]-'IS ANALYSIS'!Q8 -> 2.539 | P7: =(Table2[[#This Row],[Net Income]]-'IS ANALYSIS'!Q8)/'IS ANALYSIS'!Q8 -> #DIV/0!

Sheet WATERFALL Analysis
A1: Reporting period | B1: Prior Year NI (USD Billions) △ | C1: Rev Change (USD Billions) △ | D1: COGS Efficiency △ | E1: OpEx Efficiency △ | F1: Impact on Current NI (USD Billions) △
A2: 2025 | B2: ='VARIANCE ANALYSIS'!N3 -> 5.7 | C2: =Table5[[#This Row],[YoY ▲]] -> -5.053 | D2: =Table5[[#This Row],[YoY ▲3]] -> -1.956 | E2: =Table2[[#This Row],[ Operating Expenses ]]-'IS ANALYSIS'!E3 -> -0.488 | F2: =Table5[[#This Row],[Net Income]] -> 3.219
A3: 2024 | B3: ='VARIANCE ANALYSIS'!N4 -> 5.07 | C3: =Table5[[#This Row],[YoY ▲]] -> 0.145 | D3: =Table5[[#This Row],[YoY ▲3]] -> -0.45 | E3: =Table2[[#This Row],[ Operating Expenses ]]-'IS ANALYSIS'!E4 -> 0.199 | F3: =Table5[[#This Row],[Net Income]] -> 5.7
A4: 2023 | B4: ='VARIANCE ANALYSIS'!N5 -> 6.046 | C4: =Table5[[#This Row],[YoY ▲]] -> 4.507 | D4: =Table5[[#This Row],[YoY ▲3]] -> 3.694 | E4: =Table2[[#This Row],[ Operating Expenses ]]-'IS ANALYSIS'!E5 -> 1.573 | F4: =Table5[[#This Row],[Net Income]] -> 5.07
A5: 2022 | B5: ='VARIANCE ANALYSIS'!N6 -> 5.727 | C5: =Table5[[#This Row],[YoY ▲]] -> 2.172 | D5: =Table5[[#This Row],[YoY ▲3]] -> 0.655 | E5: =Table2[[#This Row],[ Operating Expenses ]]-'IS ANALYSIS'!E6 -> 1.779 | F5: =Table5[[#This Row],[Net Income]] -> 6.046
A6: 2021 | B6: ='VARIANCE ANALYSIS'!N7 -> 2.539 | C6: =Table5[[#This Row],[YoY ▲]] -> 7.135 | D6: =Table5[[#This Row],[YoY ▲3]] -> 3.414 | E6: =Table2[[#This Row],[ Operating Expenses ]]-'IS ANALYSIS'!E7 -> -0.101 | F6: =Table5[[#This Row],[Net Income]] -> 5.727

Sheet KPIs
A1: Perporting period | B1: 2023
A3: Sum of Free Cash Flow | B3: Sum of Cash Flow Quality | C3: Sum of Debt-to-Equity | D3: Sum of Operating Margin | E3: Sum of Return On Equity
A4: 4.872 | B4: 1.152071 | C4: 1.68002 | D4: 0.115489 | E4: 0.34625235
A8: =GETPIVOTDATA("Sum of Free Cash Flow",$A$3) -> 4.872 | B8: =GETPIVOTDATA("Sum of Cash Flow Quality",$A$3) -> 1.152071 | C8: =GETPIVOTDATA("Sum of Debt-to-Equity",$A$3) -> 1.68002 | D8: =GETPIVOTDATA("Sum of Operating Margin",$A$3) -> 0.115489 | F8: =GETPIVOTDATA("Sum of Return On Equity",$A$3) -> 0.34625235

Sheet BS ANALYSIS
A1: Reporting Period Ending: 31 May | B1: Total Current Assets | C1: Cash and Short Term Investments | D1: Cash & Equivalents | E1: Short Term Investments | F1: Receivables | G1: Inventory | H1: Other Current Assets | I1: Total Assets | J1: Total Non-Current Assets | K1: Property, Plant and Equipment | L1: Goodwill and Intangible Assets | M1: Goodwill | N1: Intangible Assets | O1: Long Term Investments | P1: Deferred Tax Assets | Q1: Other Long Term Assets | R1: Total Current Liabilities | S1: Accounts Payable | T1: Notes Payable/Short Term Debt | U1: Tax Payables | V1: Deferred Revenue | W1: Other Current Liabilities | X1: Total Liabilities | Y1: Total Non-Current Liabilities | Z1: Total Long Term Debt | AA1: Deferred Tax Liabilities Non-Current | AB1: Deferred Revenue Non-Current | AC1: Capital Lease Obligations | AD1: Other Long Term Liabilities | AE1: Total Equity | AF1: Non-Controlling Interest | AG1: Total Stockholders' Equity | AH1: Retained Earnings | AI1: Accumulated Other Earnings | AJ1: Common Stock | AK1: Preferred Stock | AL1: Additional Paid in Capital | AM1: Total Liabilities & Total Equity | AN1: Total Liabilities & Shareholders' Equity | AO1: Total Investments | AP1: Total Debt | AQ1: Net Debt | AR1: Current ratio | AS1: Working Capital | AT1: Debt-to-Equity | AU1: Debit Ratio
A2: 2025 | B2: 23.362 | C2: 9.151 | D2: 7.464 | E2: 1.687 | F2: 4.717 | G2: 7.489 | H2: 2.005 | I2: 36.579 | J2: 13.217 | K2: 7.54 | L2: 499 | M2: 240 | N2: 259 | O2: 0 | P2: 0 | Q2: 5.178 | R2: 10.566 | S2: 3.479 | T2: 507 | U2: 669 | V2: 0 | W2: 5.911 | X2: 23.366 | Y2: 12.8 | Z2: 10.511 | AA2: 0 | AB2: 0 | AC2: 3.052 | AD2: -763 | AE2: 13.213 | AF2: 0 | AG2: 13.213 | AH2: -727 | AI2: -258 | AJ2: 3 | AK2: 0 | AL2: 14.195 | AM2: 36.579 | AN2: 36.579 | AO2: 1.687 | AP2: 11.018 | AQ2: 3.554 | AR2: =Table1[[#This Row],[Total Current Assets]]/Table1[[#This Row],[Total Current Liabilities]] -> 2.2110543 | AS2: =Table1[[#This Row],[Total Current Assets]]-Table1[[#This Row],[Total Current Liabilities]] -> 12.796 | AT2: =Table1[[#This Row],[Total Liabilities]]/Table1[[#This Row],[Total Equity]] -> 1.7684099 | AU2: =Table1[[#This Row],[Total Liabilities]]/Table1[[#This Row],[Total Assets]] -> 0.63878181
A3: 2024 | B3: 25.382 | C3: 11.582 | D3: 9.86 | E3: 1.722 | F3: 4.427 | G3: 7.519 | H3: 1.854 | I3: 38.11 | J3: 12.728 | K3: 7.718 | L3: 499 | M3: 240 | N3: 259 | O3: 0 | P3: 0 | Q3: 4.511 | R3: 10.593 | S3: 2.851 | T3: 1.483 | U3: 534 | V3: 0 | W3: 5.725 | X3: 23.68 | Y3: 13.087 | Z3: 10.469 | AA3: 0 | AB3: 0 | AC3: 3.043 | AD3: -425 | AE3: 14.43 | AF3: 0 | AG3: 14.43 | AH3: 965 | AI3: 53 | AJ3: 3 | AK3: 0 | AL3: 13.409 | AM3: 38.11 | AN3: 38.11 | AO3: 1.722 | AP3: 11.952 | AQ3: 2.092 | AR3: =Table1[[#This Row],[Total Current Assets]]/Table1[[#This Row],[Total Current Liabilities]] -> 2.3961106 | AS3: =Table1[[#This Row],[Total Current Assets]]-Table1[[#This Row],[Total Current Liabilities]] -> 14.789 | AT3: =Table1[[#This Row],[Total Liabilities]]/Table1[[#This Row],[Total Equity]] -> 1.6410256 | AU3: =Table1[[#This Row],[Total Liabilities]]/Table1[[#This Row],[Total Assets]] -> 0.62135922
A4: 2023 | B4: 25.202 | C4: 10.675 | D4: 7.441 | E4: 3.234 | F4: 4.131 | G4: 8.454 | H4: 1.942 | I4: 37.531 | J4: 12.329 | K4: 8.004 | L4: 555 | M4: 281 | N4: 274 | O4: 0 | P4: 0 | Q4: 3.77 | R4: 9.256 | S4: 2.862 | T4: 431 | U4: 240 | V4: 0 | W4: 5.723 | X4: 23.527 | Y4: 14.271 | Z4: 11.713 | AA4: 0 | AB4: 0 | AC4: 3.211 | AD4: -653 | AE4: 14.004 | AF4: 0 | AG4: 14.004 | AH4: 1.358 | AI4: 231 | AJ4: 3 | AK4: 0 | AL4: 12.412 | AM4: 37.531 | AN4: 37.531 | AO4: 3.234 | AP4: 12.144 | AQ4: 4.703 | AR4: =Table1[[#This Row],[Total Current Assets]]/Table1[[#This Row],[Total Current Liabilities]] -> 2.7227744 | AS4: =Table1[[#This Row],[Total Current Assets]]-Table1[[#This Row],[Total Current Liabilities]] -> 15.946 | AT4: =Table1[[#This Row],[Total Liabilities]]/Table1[[#This Row],[Total Equity]] -> 1.68002 | AU4: =Table1[[#This Row],[Total Liabilities]]/Table1[[#This Row],[Total Assets]] -> 0.62686846
A5: 2022 | B5: 28.213 | C5: 12.997 | D5: 8.574 | E5: 4.423 | F5: 4.667 | G5: 8.42 | H5: 2.129 | I5: 40.321 | J5: 12.108 | K5: 7.717 | L5: 570 | M5: 284 | N5: 286 | O5: 0 | P5: 3.821 | Q5: 0 | R5: 10.73 | S5: 3.358 | T5: 930 | U5: 222 | V5: 0 | W5: 6.22 | X5: 25.04 | Y5: 14.31 | Z5: 11.697 | AA5: 2.613 | AB5: 0 | AC5: 3.197 | AD5: -3.197 | AE5: 15.281 | AF5: 0 | AG5: 15.281 | AH5: 3.476 | AI5: 318 | AJ5: 3 | AK5: 0 | AL5: 11.484 | AM5: 40.321 | AN5: 40.321 | AO5: 4.423 | AP5: 12.627 | AQ5: 4.053 | AR5: =Table1[[#This Row],[Total Current Assets]]/Table1[[#This Row],[Total Current Liabilities]] -> 2.6293569 | AS5: =Table1[[#This Row],[Total Current Assets]]-Table1[[#This Row],[Total Current Liabilities]] -> 17.483 | AT5: =Table1[[#This Row],[Total Liabilities]]/Table1[[#This Row],[Total Equity]] -> 1.6386362 | AU5: =Table1[[#This Row],[Total Liabilities]]/Table1[[#This Row],[Total Assets]] -> 0.62101634
A6: 2021 | B6: 26.291 | C6: 13.476 | D6: 9.889 | E6: 3.587 | F6: 4.463 | G6: 6.854 | H6: 1.498 | I6: 37.74 | J6: 11.449 | K6: 8.017 | L6: 511 | M6: 242 | N6: 269 | O6: 0 | P6: 2.921 | Q6: 0 | R6: 9.674 | S6: 2.836 | T6: 469 | U6: 306 | V6: 0 | W6: 6.063 | X6: 24.973 | Y6: 15.299 | Z6: 12.344 | AA6: 2.955 | AB6: 0 | AC6: 3.398 | AD6: -3.398 | AE6: 12.767 | AF6: 0 | AG6: 12.767 | AH6: 3.179 | AI6: -380 | AJ6: 3 | AK6: 0 | AL6: 9.965 | AM6: 37.74 | AN6: 37.74 | AO6: 3.587 | AP6: 12.813 | AQ6: 2.924 | AR6: =Table1[[#This Row],[Total Current Assets]]/Table1[[#This Row],[Total Current Liabilities]] -> 2.7176969 | AS6: =Table1[[#This Row],[Total Current Assets]]-Table1[[#This Row],[Total Current Liabilities]] -> 16.617 | AT6: =Table1[[#This Row],[Total Liabilities]]/Table1[[#This Row],[Total Equity]] -> 1.9560586 | AU6: =Table1[[#This Row],[Total Liabilities]]/Table1[[#This Row],[Total Assets]] -> 0.66171171
A7: 2020 | B7: 20.556 | C7: 8.787 | D7: 8.348 | E7: 439 | F7: 2.749 | G7: 7.367 | H7: 1.653 | I7: 31.342 | J7: 10.786 | K7: 7.963 | L7: 497 | M7: 223 | N7: 274 | O7: 0 | P7: 2.326 | Q7: 0 | R7: 8.284 | S7: 2.248 | T7: 696 | U7: 156 | V7: 0 | W7: 5.184 | X7: 23.287 | Y7: 15.003 | Z7: 12.319 | AA7: 2.684 | AB7: 0 | AC7: 3.358 | AD7: -3.358 | AE7: 8.055 | AF7: 0 | AG7: 8.055 | AH7: -191 | AI7: -56 | AJ7: 3 | AK7: 0 | AL7: 8.299 | AM7: 31.342 | AN7: 31.342 | AO7: 439 | AP7: 13.015 | AQ7: 4.667 | AR7: =Table1[[#This Row],[Total Current Assets]]/Table1[[#This Row],[Total Current Liabilities]] -> 2.4814099 | AS7: =Table1[[#This Row],[Total Current Assets]]-Table1[[#This Row],[Total Current Liabilities]] -> 12.272 | AT7: =Table1[[#This Row],[Total Liabilities]]/Table1[[#This Row],[Total Equity]] -> 2.8909994 | AU7: =Table1[[#This Row],[Total Liabilities]]/Table1[[#This Row],[Total Assets]] -> 0.74299662

Sheet CF ANALYSIS
A1: Reporting Period Ending: 31 May | B1: Net Income/Starting Line | C1: Cash From Operating Activities | D1: Depreciation and Amortization | E1: Deferred Income Tax | F1: Stock Based Compensation | G1: Other Non-Cash Items | H1: Changes in Working Capital | I1: Accounts Receivable | J1: Inventory | K1: Accounts Payable | L1: Deferred Revenue | M1: Other Working Capital | N1: Cash From Investing Activities | O1: Investments in Property Plant and Equipment | P1: Payments for Acquisitions | Q1: Purchases of Securities | R1: Sales and Maturities of Investments | S1: Other Investing Activities | T1: Cash From Financing Activities | U1: Debt Repayment | V1: Common Stock Issued | W1: Common Stock Repurchased | X1: Dividends Paid | Y1: Other Financing Activities | Z1: Effect of Forex Changes on Cash | AA1: Net Change in Cash | AB1: Cash at Beginning of Period | AC1: Cash at End of Period | AD1: Free Cash Flow | AE1: Operating Cash Flow | AF1: Capital Expenditure | AG1: Cash flow Quality
A2: 2025 | B2: 3.219 | C2: 3.698 | D2: 775 | E2: -288 | F2: 709 | G2: 70 | H2: -787 | I2: -257 | J2: 120 | K2: -426 | L2: -224 | M2: 0 | N2: -275 | O2: -430 | P2: 0 | Q2: -3.234 | R2: 3.381 | S2: 8 | T2: -5.82 | U2: -1.001 | V2: 551 | W2: -2.985 | X2: -2.3 | Y2: -85 | Z2: 1 | AA2: -2.396 | AB2: 9.86 | AC2: 7.464 | AD2: 3.268 | AE2: 3.698 | AF2: -430 | AG2: =Table3[[#This Row],[Operating Cash Flow]]/Table3[[#This Row],[Net Income/Starting Line]] -> 1.148804
A3: 2024 | B3: 5.7 | C3: 7.429 | D3: 844 | E3: -497 | F3: 804 | G3: -138 | H3: 716 | I3: -329 | J3: 908 | K3: 397 | L3: -260 | M3: 0 | N3: 894 | O3: -812 | P3: 0 | Q3: -4.767 | R3: 6.488 | S3: -15 | T3: -5.888 | U3: 0 | V3: 0 | W3: -4.25 | X3: -2.169 | Y3: 531 | Z3: -16 | AA3: 2.419 | AB3: 7.441 | AC3: 9.86 | AD3: 6.617 | AE3: 7.429 | AF3: -812 | AG3: =Table3[[#This Row],[Operating Cash Flow]]/Table3[[#This Row],[Net Income/Starting Line]] -> 1.3033333
A4: 2023 | B4: 5.07 | C4: 5.841 | D4: 859 | E4: -117 | F4: 755 | G4: -213 | H4: -513 | I4: 489 | J4: -133 | K4: -225 | L4: -644 | M4: 0 | N4: 564 | O4: -969 | P4: 0 | Q4: -6.059 | R4: 7.54 | S4: 52 | T4: -7.447 | U4: -504 | V4: 0 | W4: -5.48 | X4: -2.012 | Y4: 549 | Z4: -91 | AA4: -1.133 | AB4: 8.574 | AC4: 7.441 | AD4: 4.872 | AE4: 5.841 | AF4: -969 | AG4: =Table3[[#This Row],[Operating Cash Flow]]/Table3[[#This Row],[Net Income/Starting Line]] -> 1.152071
A5: 2022 | B5: 6.046 | C5: 5.188 | D5: 840 | E5: -650 | F5: 638 | G5: -26 | H5: -1.66 | I5: -504 | J5: -1.676 | K5: 1.365 | L5: -845 | M5: 0 | N5: -1.524 | O5: -758 | P5: 0 | Q5: -12.913 | R5: 12.166 | S5: -19 | T5: -4.836 | U5: 15 | V5: 0 | W5: -4.014 | X5: -1.837 | Y5: 1 | Z5: -143 | AA5: -1.315 | AB5: 9.889 | AC5: 8.574 | AD5: 4.43 | AE5: 5.188 | AF5: -758 | AG5: =Table3[[#This Row],[Operating Cash Flow]]/Table3[[#This Row],[Net Income/Starting Line]] -> 0.85808799
A6: 2021 | B6: 5.727 | C6: 6.657 | D6: 797 | E6: -385 | F6: 611 | G6: -138 | H6: 45 | I6: -1.606 | J6: 507 | K6: 1.326 | L6: -182 | M6: 0 | N6: -3.8 | O6: -695 | P6: 0 | Q6: -9.961 | R6: 6.685 | S6: 171 | T6: -1.459 | U6: -249 | V6: 0 | W6: -608 | X6: -1.638 | Y6: 1.036 | Z6: 143 | AA6: 1.541 | AB6: 8.348 | AC6: 9.889 | AD6: 5.962 | AE6: 6.657 | AF6: -695 | AG6: =Table3[[#This Row],[Operating Cash Flow]]/Table3[[#This Row],[Net Income/Starting Line]] -> 1.1623887

Sheet Forecast Analysis
A1: Year | B1: Revenue Actual | C1: Revenue(Forecast)
A2: 2020 | B2: ='IS ANALYSIS'!B7 -> 37.403
A3: 2021 | B3: ='IS ANALYSIS'!B6 -> 44.538
A4: 2022 | B4: ='IS ANALYSIS'!B5 -> 46.71
A5: 2023 | B5: ='IS ANALYSIS'!B4 -> 51.217
A6: 2024 | B6: ='IS ANALYSIS'!B3 -> 51.362
A7: 2025 | B7: ='IS ANALYSIS'!B2 -> 46.309
A8: 2026 | C8: =_xlfn.FORECAST.LINEAR(A8,B2:B7,A2:A7) -> 53.2074
A9: 2027 | C9: =_xlfn.FORECAST.LINEAR(A9,B3:B8,A3:A8) -> 51.3048

Sheet DIVIDENDS ANALYSIS
A1: Period Ending: | B1: Dividend per Share | C1: Reference Market Share Price | D1: Dividend Yield | E1: Earnings Per Share | F1: Payout Ratio | G1: Price to earning | H1: Price-to-Book
A2: 2025 | B2: =_xlfn.NUMBERVALUE('NKE DIVIDENDS'!B9,".",",") -> 1.61 | C2: =_xlfn.NUMBERVALUE('NKE DIVIDENDS'!C9,".",",") -> 63.71 | D2: =_xlfn.NUMBERVALUE('NKE DIVIDENDS'!D9,".",",") -> 0.0253 | E2: =_xlfn.NUMBERVALUE('NKE DIVIDENDS'!E9,".",",") -> 2.17 | F2: =_xlfn.NUMBERVALUE('NKE DIVIDENDS'!F9,".",",") -> 0.7419 | G2: =C2/E2 -> 29.359447 | H2: =93.52/Table1[[#This Row],[Total Equity]] -> 7.0778778
A3: 2024 | B3: =_xlfn.NUMBERVALUE('NKE DIVIDENDS'!B10,".",",") -> 1.51 | C3: =_xlfn.NUMBERVALUE('NKE DIVIDENDS'!C10,".",",") -> 75.67 | D3: =_xlfn.NUMBERVALUE('NKE DIVIDENDS'!D10,".",",") -> 0.02 | E3: =_xlfn.NUMBERVALUE('NKE DIVIDENDS'!E10,".",",") -> 3.76 | F3: =_xlfn.NUMBERVALUE('NKE DIVIDENDS'!F10,".",",") -> 0.4016 | G3: =C3/E3 -> 20.125 | H3: =93.52/Table1[[#This Row],[Total Equity]] -> 6.4809425
A4: 2023 | B4: =_xlfn.NUMBERVALUE('NKE DIVIDENDS'!B11,".",",") -> 1.39 | C4: =_xlfn.NUMBERVALUE('NKE DIVIDENDS'!C11,".",",") -> 108.6 | D4: =_xlfn.NUMBERVALUE('NKE DIVIDENDS'!D11,".",",") -> 0.0128 | E4: =_xlfn.NUMBERVALUE('NKE DIVIDENDS'!E11,".",",") -> 3.27 | F4: =_xlfn.NUMBERVALUE('NKE DIVIDENDS'!F11,".",",") -> 0.4251 | G4: =C4/E4 -> 33.211009 | H4: =93.52/Table1[[#This Row],[Total Equity]] -> 6.678092
A5: 2022 | B5: =_xlfn.NUMBERVALUE('NKE DIVIDENDS'!B12,".",",") -> 1.25 | C5: =_xlfn.NUMBERVALUE('NKE DIVIDENDS'!C12,".",",") -> 117 | D5: =_xlfn.NUMBERVALUE('NKE DIVIDENDS'!D12,".",",") -> 0.0107 | E5: =_xlfn.NUMBERVALUE('NKE DIVIDENDS'!E12,".",",") -> 3.83 | F5: =_xlfn.NUMBERVALUE('NKE DIVIDENDS'!F12,".",",") -> 0.3264 | G5: =C5/E5 -> 30.548303 | H5: =93.52/Table1[[#This Row],[Total Equity]] -> 6.1200183
A6: 2021 | B6: =_xlfn.NUMBERVALUE('NKE DIVIDENDS'!B13,".",",") -> 1.13 | C6: =_xlfn.NUMBERVALUE('NKE DIVIDENDS'!C13,".",",") -> 166.7 | D6: =_xlfn.NUMBERVALUE('NKE DIVIDENDS'!D13,".",",") -> 0.00678 | E6: =_xlfn.NUMBERVALUE('NKE DIVIDENDS'!E13,".",",") -> 3.64 | F6: =_xlfn.NUMBERVALUE('NKE DIVIDENDS'!F13,".",",") -> 0.3104 | G6: =C6/E6 -> 45.796703 | H6: =93.52/Table1[[#This Row],[Total Equity]] -> 7.3251351
A7: 2020 | B7: =_xlfn.NUMBERVALUE('NKE DIVIDENDS'!B14,".",",") -> 1.01 | C7: =_xlfn.NUMBERVALUE('NKE DIVIDENDS'!C14,".",",") -> 141.5 | D7: =_xlfn.NUMBERVALUE('NKE DIVIDENDS'!D14,".",",") -> 0.00714 | E7: =_xlfn.NUMBERVALUE('NKE DIVIDENDS'!E14,".",",") -> 1.63 | F7: =_xlfn.NUMBERVALUE('NKE DIVIDENDS'!F14,".",",") -> 0.6196 | G7: =C7/E7 -> 86.809816 | H7: =93.52/Table1[[#This Row],[Total Equity]] -> 11.61018

Sheet waterfall helper
A1: Label | B1: Amount
A2: Prior Year NI | B2: =GETPIVOTDATA("Amount",'Waterfall Pivot'!$A$3,"Label","Prior Year NI (USD Billions) △") -> 6.046
A3: Rev Change △ | B3: =GETPIVOTDATA("Amount",'Waterfall Pivot'!$A$3,"Label","Rev Change (USD Billions) △") -> 4.507
A4: COGS Efficiency △ | B4: =GETPIVOTDATA("Amount",'Waterfall Pivot'!$A$3,"Label","COGS Efficiency △") -> 3.694
A5: OpEx Efficiency △ | B5: =GETPIVOTDATA("Amount",'Waterfall Pivot'!$A$3,"Label","OpEx Efficiency △") -> 1.573
A6: Impact on Current NI | B6: =GETPIVOTDATA("Amount",'Waterfall Pivot'!$A$3,"Label","Impact on Current NI (USD Billions) △") -> 5.07

Sheet Forecast Pivot
A3: Row Labels | B3: Actual | C3: Forecast
A4: 2020 | B4: 37.403
A5: 2021 | B5: 44.538
A6: 2022 | B6: 46.71
A7: 2023 | B7: 51.217
A8: 2024 | B8: 51.362
A9: 2025 | B9: 46.309
A10: 2026 | C10: 53.2074
A11: 2027 | C11: 51.3048
A12: Grand Total | B12: 277.539 | C12: 104.5122

Sheet Waterfall Pivot
A1: Year | B1: 2023
A3: Row Labels | B3: Sum of Amount
A4: COGS Efficiency △ | B4: 3.694
A5: Impact on Current NI (USD Billions) △ | B5: 5.07
A6: OpEx Efficiency △ | B6: 1.573
A7: Prior Year NI (USD Billions) △ | B7: 6.046
A8: Rev Change (USD Billions) △ | B8: 4.507
A9: Grand Total | B9: 20.89

Sheet Benchmark Pivots
A3: Sum of Operating Margin | B3: Column Labels
A4: Row Labels | B4: Industry Margin | C4: Nike | D4: Grand Total
A5: 2021 | B5: 0.1710168 | C5: 0.15575464 | D5: 0.32677144
A6: 2022 | B6: 0.17610939 | C6: 0.14290302 | D6: 0.31901241
A7: 2023 | B7: 0.13960863 | C7: 0.115489 | D7: 0.25509763
A8: 2024 | B8: 0.17231078 | C8: 0.12287294 | D8: 0.29518372
A9: 2025 | B9: 0.23777035 | C9: 0.079941264 | D9: 0.31771162
A10: Grand Total | B10: 0.89681596 | C10: 0.61696086 | D10: 1.5137768

Sheet Benchmarks
A1: Operating Margin | B1: 2021 | C1: 2022 | D1: 2023 | E1: 2024 | F1: 2025
A2: NIKE (NKE) | B2: ='IS ANALYSIS'!Y6 -> 0.15575464 | C2: ='IS ANALYSIS'!Y5 -> 0.14290302 | D2: ='IS ANALYSIS'!Y4 -> 0.115489 | E2: ='IS ANALYSIS'!Y3 -> 0.12287294 | F2: =Table2[[#This Row],[Operating Margin]] -> 0.079941264
A3: Adidas (ADDYY) | B3: ='Benchmarks analysis'!D9 -> 0.093529246 | C3: ='Benchmarks analysis'!D10 -> 0.029718804 | D3: ='Benchmarks analysis'!D11 -> 0.012507584 | E3: ='Benchmarks analysis'!D12 -> 0.056453997 | F3: ='Benchmarks analysis'!D13 -> 0.78906883
A4: Anta Sportswear (2020.HK) | B4: ='Benchmarks analysis'!D16 -> 0.22277408 | C4: ='Benchmarks analysis'!D17 -> 0.20931576 | D4: ='Benchmarks analysis'!D18 -> 0.2464398 | E4: ='Benchmarks analysis'!D19 -> 0.23430661 | F4: ='Benchmarks analysis'!D20 -> 0.23885767
A5: Lululemon (LULU) | B5: ='Benchmarks analysis'!D2 -> 0.18627896 | C5: ='Benchmarks analysis'!D3 -> 0.21304139 | D5: ='Benchmarks analysis'!D4 -> 0.16372827 | E5: ='Benchmarks analysis'!D5 -> 0.22174862 | F5: ='Benchmarks analysis'!D6 -> 0.23668304
A6: Industry Margin | B6: =MEDIAN(B2:B5) -> 0.1710168 | C6: =MEDIAN(C2:C5) -> 0.17610939 | D6: =MEDIAN(D2:D5) -> 0.13960863 | E6: =MEDIAN(E2:E5) -> 0.17231078 | F6: =MEDIAN(F2:F5) -> 0.23777035
A8: Year | B8: Entity | C8: Operating Margin
A9: 2021 | B9: Nike | C9: =B2 -> 0.15575464
A10: 2021 | B10: Adidas | C10: =B3 -> 0.093529246
A11: 2021 | B11: Anta Sportswear | C11: =B4 -> 0.22277408
A12: 2021 | B12: Lululemon | C12: =B5 -> 0.18627896
A13: 2021 | B13: Industry Margin | C13: =B6 -> 0.1710168
A14: 2022 | B14: Nike | C14: =C2 -> 0.14290302
A15: 2022 | B15: Adidas | C15: =C3 -> 0.029718804
A16: 2022 | B16: Anta Sportswear | C16: =C4 -> 0.20931576
A17: 2022 | B17: Lululemon | C17: =C5 -> 0.21304139
A18: 2022 | B18: Industry Margin | C18: =C6 -> 0.17610939
A19: 2023 | B19: Nike | C19: =D2 -> 0.115489
A20: 2023 | B20: Adidas | C20: =D3 -> 0.012507584
A21: 2023 | B21: Anta Sportswear | C21: =D4 -> 0.2464398
A22: 2023 | B22: Lululemon | C22: =D5 -> 0.16372827
A23: 2023 | B23: Industry Margin | C23: =D6 -> 0.13960863
A24: 2024 | B24: Nike | C24: =E2 -> 0.12287294
A25: 2024 | B25: Adidas | C25: =E3 -> 0.056453997
A26: 2024 | B26: Anta Sportswear | C26: =E4 -> 0.23430661
A27: 2024 | B27: Lululemon | C27: =E5 -> 0.22174862
A28: 2024 | B28: Industry Margin | C28: =E6 -> 0.17231078
A29: 2025 | B29: Nike | C29: =F2 -> 0.079941264
A30: 2025 | B30: Adidas | C30: =F3 -> 0.78906883
A31: 2025 | B31: Anta Sportswear | C31: =F4 -> 0.23885767
A32: 2025 | B32: Lululemon | C32: =F5 -> 0.23668304
A33: 2025 | B33: Industry Margin | C33: =F6 -> 0.23777035

Sheet ADDYY
A1: Period Ending: | B1: LTM (Last Twelve Months) | C1: 2024 12-31 | D1: 2023 12-31 | E1: 2022 12-31 | F1: 2021 12-31 | G1: 2020 12-31
A2: Report Filing | B2: 2025-09-30 | C2: 2024-12-31 | D2: 2023-12-31 | E2: 2022-12-31 | F2: 2021-12-31 | G2: 2020-12-31
A3: Revenue | B3: 24700 | C3: 23683 | D3: 21427 | E3: 22511 | F3: 21234 | G3: 19844
A4: Cost of Revenue | B4: 12014 | C4: 11658 | D4: 11244 | E4: 11867 | F4: 10469 | G4: 9990
A5: Gross Profit | B5: 12686 | C5: 12025 | D5: 10183 | E5: 10644 | F5: 10765 | G5: 9854
A6: Operating Expenses | B6: 10737 | C6: 10688 | D6: 9915 | E6: 9975 | F6: 8779 | G6: 9103
A7: Research & Development | B7: 0 | C7: 0 | D7: 151 | E7: 153 | F7: 130 | G7: 115
A8: Selling General and Administrative | B8: 12954 | C8: 10915 | D8: 9914 | E8: 10015 | F8: 8810 | G8: 8996
A9: Other Operating Expenses | B9: -2217 | C9: -227 | D9: -150 | E9: -193 | F9: -161 | G9: -8
A10: Operating Income | B10: 1949 | C10: 1337 | D10: 268 | E10: 669 | F10: 1986 | G10: 751
A11: Net Non-Operating Interest | B11: -218.5 | C11: -164 | D11: -121 | E11: -114 | F11: -165 | G11: -139
A12: Interest Income | B12: 41.02 | C12: 57 | D12: 39 | E12: 23 | F12: 12 | G12: 25
A13: Interest Expense | B13: 259.5 | C13: 221 | D13: 160 | E13: 137 | F13: 177 | G13: 164
A14: Equity & Other Income/(Expense) | B14: -35.5 | C14: -52 | D14: -81 | E14: -167 | F14: 31 | G14: -37
A15: Income Before Tax | B15: 1695 | C15: 1121 | D15: 66 | E15: 388 | F15: 1852 | G15: 575
A16: Income Tax Expense | B16: 430 | C16: 297 | D16: 124 | E16: 134 | F16: 360 | G16: 146
A17: Income Attributable to Non-Controlling Interest | B17: 46 | C17: 60 | D17: 17 | E17: 0 | F17: 0 | G17: -3
A18: Net Income | B18: 1219 | C18: 764 | D18: -75 | E18: 254 | F18: 1492 | G18: 432
A19: Depreciation and Amortization | B19: 1137 | C19: 1171 | D19: 505 | E19: 1221 | F19: 1142 | G19: 1244
A20: EBITDA | B20: 3086 | C20: 2508 | D20: 773 | E20: 1890 | F20: 3128 | G20: 1995
A21: Earnings Per Share (EPS) | B21: 3.41 | C21: 2.14 | D21: -0.21 | E21: 0.7 | F21: 3.84 | G21: 1.11
A22: Diluted Earnings Per Share | B22: 3.41 | C22: 2.14 | D22: -0.21 | E22: 0.7 | F22: 3.84 | G22: 1.11
A23: Weighted Average Shares Outstanding | B23: 357.4 | C23: 357.1 | D23: 357.1 | E23: 366.5 | F23: 388.3 | G23: 390.3
A24: Diluted Weighted Average Shares Outstanding | B24: 357.4 | C24: 357.1 | D24: 357.1 | E24: 366.5 | F24: 388.4 | G24: 390.3
A27: Period Ending: | C27: Revenue | D27: Cost of Revenue | E27: Gross Profit | F27: Operating Expenses | G27: Research & Development | H27: Selling General and Administrative | I27: Other Operating Expenses | J27: Operating Income | K27: Net Non-Operating Interest | L27: Interest Income | M27: Interest Expense | N27: Equity & Other Income/(Expense) | O27: Income Before Tax | P27: Income Tax Expense | Q27: Income Attributable to Non-Controlling Interest | R27: Net Income
A28: LTM (Last Twelve Months) | C28: 2470 | D28: 12014 | E28: 12686 | F28: 10737 | G28: 0 | H28: 12954 | I28: -2217 | J28: 1949 | K28: -218.5 | L28: 41.02 | M28: 259.5 | N28: -35.5 | O28: 1695 | P28: 430 | Q28: 46 | R28: 1219
A29: 2024 12-31 | C29: 23683 | D29: 11658 | E29: 12025 | F29: 10688 | G29: 0 | H29: 10915 | I29: -227 | J29: 1337 | K29: -164 | L29: 57 | M29: 221 | N29: -52 | O29: 1121 | P29: 297 | Q29: 60 | R29: 764
A30: 2023 12-31 | C30: 21427 | D30: 11244 | E30: 10183 | F30: 9915 | G30: 151 | H30: 9914 | I30: -150 | J30: 268 | K30: -121 | L30: 39 | M30: 160 | N30: -81 | O30: 66 | P30: 124 | Q30: 17 | R30: -75
A31: 2022 12-31 | C31: 22511 | D31: 11867 | E31: 10644 | F31: 9975 | G31: 153 | H31: 10015 | I31: -193 | J31: 669 | K31: -114 | L31: 23 | M31: 137 | N31: -167 | O31: 388 | P31: 134 | Q31: 0 | R31: 254
A32: 2021 12-31 | C32: 21234 | D32: 10469 | E32: 10765 | F32: 8779 | G32: 130 | H32: 881 | I32: -161 | J32: 1986 | K32: -165 | L32: 12 | M32: 177 | N32: 31 | O32: 1852 | P32: 360 | Q32: 0 | R32: 1492
A33: 2020 12-31 | C33: 19844 | D33: 999 | E33: 9854 | F33: 9103 | G33: 115 | H33: 8996 | I33: -8 | J33: 751 | K33: -139 | L33: 25 | M33: 164 | N33: -37 | O33: 575 | P33: 146 | Q33: -3 | R33: 432

Sheet Anta
A1: Period Ending: | B1: LTM (Last Twelve Months) | C1: 2024 12-31 | D1: 2023 12-31 | E1: 2022 12-31 | F1: 2021 12-31 | G1: 2020 12-31 | J1: Period Ending: | K1: Revenue | L1: Cost of Revenue | M1: Gross Profit | N1: Operating Expenses | O1: Research & Development | P1: Selling, General and Administrative | Q1: Other Operating Expenses | R1: Operating Income | S1: Net Non-Operating Interest | T1: Interest Income | U1: Interest Expense | V1: Equity & Other Income/(Expense) | W1: Income Before Tax | X1: Income Tax Expense | Y1: Income Attributable to Non-Controlling Interest | Z1: Net Income | AA1: Depreciation and Amortization
A2: Report Filing | B2: 2025-06-30 | C2: 2024-12-31 | D2: 2023-12-31 | E2: 2022-12-31 | F2: 2021-12-31 | G2: 2020-12-31 | J2: LTM (Last Twelve Months) | K2: 75.635 | L2: 28.796 | M2: 46.839 | N2: 28.773 | O2: 72 | P2: 31.687 | Q2: -2.986 | R2: 18.066 | S2: 1.676 | T2: 2.302 | U2: 626 | V2: 2.373 | W2: 22.115 | X2: 5.434 | Y2: 1.775 | Z2: 14.906 | AA2: 5.643
A3: Revenue | B3: 75,635 | C3: 70,826 | D3: 62,356 | E3: 53,651 | F3: 49,328 | G3: 35,512 | J3: 2024 12-31 | K3: 70.826 | L3: 26.794 | M3: 44.032 | N3: 27.437 | O3: 0 | P3: 29.845 | Q3: -2.408 | R3: 16.595 | S3: 1.22 | T3: 1.846 | U3: 626 | V3: 4.069 | W3: 21.884 | X3: 4.895 | Y3: 1.393 | Z3: 15.596 | AA3: 5.471
A4: Cost of Revenue | B4: 28,796 | C4: 26,794 | D4: 23,328 | E4: 21,333 | F4: 18,924 | G4: 14,861 | J4: 2023 12-31 | K4: 62.356 | L4: 23.328 | M4: 39.028 | N4: 23.661 | O4: 0 | P4: 25.366 | Q4: -1.705 | R4: 15.367 | S4: 949 | T4: 1.47 | U4: 521 | V4: -676 | W4: 15.64 | X4: 4.363 | Y4: 1.041 | Z4: 10.236 | AA4: 4.987
A5: Gross Profit | B5: 46,839 | C5: 44,032 | D5: 39,028 | E5: 32,318 | F5: 30,404 | G5: 20,651 | J5: 2022 12-31 | K5: 53.651 | L5: 21.333 | M5: 32.318 | N5: 21.088 | O5: 1.447 | P5: 23.216 | Q5: -3.575 | R5: 11.23 | S5: 98 | T5: 609 | U5: 511 | V5: 27 | W5: 11.355 | X5: 3.11 | Y5: 655 | Z5: 7.59 | AA5: 4.464
A6: Operating Expenses | B6: 28,773 | C6: 27,437 | D6: 23,661 | E6: 21,088 | F6: 19,415 | G6: 11,499 | J6: 2021 12-31 | K6: 49.328 | L6: 18.924 | M6: 30.404 | N6: 19.415 | O6: 1.116 | P6: 20.681 | Q6: -2.382 | R6: 10.989 | S6: -51 | T6: 392 | U6: 443 | V6: 302 | W6: 11.24 | X6: 3.021 | Y6: 499 | Z6: 7.72 | AA6: 3.266
A7: Research & Development | B7: 72 | C7: 0 | D7: 0 | E7: 1,447 | F7: 1,116 | G7: 871 | J7: 2020 12-31 | K7: 35.512 | L7: 14.861 | M7: 20.651 | N7: 11.499 | O7: 871 | P7: 12.888 | Q7: -2.26 | R7: 9.152 | S7: -136 | T7: 271 | U7: 407 | V7: -927 | W7: 8.089 | X7: 2.52 | Y7: 407 | Z7: 5.162 | AA7: 2.079
A8: Selling, General and Administrative | B8: 31,687 | C8: 29,845 | D8: 25,366 | E8: 23,216 | F8: 20,681 | G8: 12,888
A9: Other Operating Expenses | B9: -2,986 | C9: -2,408 | D9: -1,705 | E9: -3,575 | F9: -2,382 | G9: -2,260
A10: Operating Income | B10: 18,066 | C10: 16,595 | D10: 15,367 | E10: 11,230 | F10: 10,989 | G10: 9,152
A11: Net Non-Operating Interest | B11: 1,676 | C11: 1,220 | D11: 949 | E11: 98 | F11: -51 | G11: -136
A12: Interest Income | B12: 2,302 | C12: 1,846 | D12: 1,470 | E12: 609 | F12: 392 | G12: 271
A13: Interest Expense | B13: 626 | C13: 626 | D13: 521 | E13: 511 | F13: 443 | G13: 407
A14: Equity & Other Income/(Expense) | B14: 2,373 | C14: 4,069 | D14: -676 | E14: 27 | F14: 302 | G14: -927
A15: Income Before Tax | B15: 22,115 | C15: 21,884 | D15: 15,640 | E15: 11,355 | F15: 11,240 | G15: 8,089
A16: Income Tax Expense | B16: 5,434 | C16: 4,895 | D16: 4,363 | E16: 3,110 | F16: 3,021 | G16: 2,520
A17: Income Attributable to Non-Controlling Interest | B17: 1,775 | C17: 1,393 | D17: 1,041 | E17: 655 | F17: 499 | G17: 407
A18: Net Income | B18: 14,906 | C18: 15,596 | D18: 10,236 | E18: 7,590 | F18: 7,720 | G18: 5,162
A19: Depreciation and Amortization | B19: 5,643 | C19: 5,471 | D19: 4,987 | E19: 4,464 | F19: 3,266 | G19: 2,079
... A24: Diluted Weighted Average Shares Outstanding | B24: 2,903 | C24: 2,906 | D24: 2,867 | E24: 2,781 | F24: 2,776 | G24: 2,768

Sheet Lulu
A1: Period Ending: | B1: LTM (Last Twelve Months) | C1: 2025 02-02 | D1: 2024 01-28 | E1: 2023 01-29 | F1: 2022 01-30 | G1: 2021 01-31 | H1: 2020 02-02 | J1: Period Ending: | K1: Revenue | L1: Cost of Revenue | M1: Gross Profit | N1: Operating Expenses | O1: Research & Development | P1: Selling General and Administrative | Q1: Other Operating Expenses | R1: Operating Income | S1: Net Non-Operating Interest | T1: Interest Income | U1: Interest Expense | V1: Equity & Other Income/(Expense) | W1: Income Before Tax | X1: Income Tax Expense | Y1: Income Attributable to Non-Controlling Interest | Z1: Net Income
A2: Report Filing | B2: 2025-12-11 | C2: 2025-03-27 | D2: 2024-03-21 | E2: 2023-03-28 | F2: 2022-03-29 | G2: 2021-03-30 | H2: 2020-03-26 | J2: LTM (Last Twelve Months) | K2: 11073 | L2: 4605 | M2: 6468 | N2: 4019 | O2: 0 | P2: 4021 | Q2: -2.05 | R2: 2449 | S2: 0 | T2: 0 | U2: 0 | V2: 33.93 | W2: 2483 | X2: 742.5 | Y2: 0 | Z2: 1741
A3: Revenue | B3: 11073 | C3: 10588 | D3: 9619 | E3: 8111 | F3: 6257 | G3: 4402 | H3: 3979 | J3: 2025 02-02 | K3: 10588 | L3: 4317 | M3: 6271 | N3: 3765 | O3: 0 | P3: 3762 | Q3: 2.73 | R3: 2506 | S3: 0 | T3: 0 | U3: 0 | V3: 70.38 | W3: 2576 | X3: 761.5 | Y3: 0 | Z3: 1815
A4: Cost of Revenue | B4: 4605 | C4: 4317 | D4: 4010 | E4: 3618 | F4: 2648 | G4: 1938 | H4: 1756 | J4: 2024 01-28 | K4: 9619 | L4: 401 | M4: 5609 | N4: 3477 | O4: 0 | P4: 3397 | Q4: 79.51 | R4: 2133 | S4: 0 | T4: 0 | U4: 0 | V4: 43.06 | W4: 2176 | X4: 625.5 | Y4: 0 | Z4: 155
A5: Gross Profit | B5: 6468 | C5: 6271 | D5: 5609 | E5: 4492 | F5: 3609 | G5: 2464 | H5: 2223 | J5: 2023 01-29 | K5: 8111 | L5: 3618 | M5: 4492 | N5: 3164 | O5: 0 | P5: 2757 | Q5: 406.5 | R5: 1328 | S5: 0 | T5: 0 | U5: 0 | V5: 4.16 | W5: 1333 | X5: 477.8 | Y5: 0 | Z5: 854.8
A6: Operating Expenses | B6: 4019 | C6: 3765 | D6: 3477 | E6: 3164 | F6: 2275 | G6: 1644 | H6: 1334 | J6: 2022 01-30 | K6: 6257 | L6: 2648 | M6: 3609 | N6: 2275 | O6: 0 | P6: 2225 | Q6: 50.18 | R6: 1333 | S6: 0 | T6: 0 | U6: 0 | V6: 0.514 | W6: 1334 | X6: 358.5 | Y6: 0 | Z6: 975.3
A7: Research & Development | B7: 0 | C7: 0 | D7: 0 | E7: 0 | F7: 0 | G7: 0 | H7: 0 | J7: 2021 01-31 | K7: 4402 | L7: 1938 | M7: 2464 | N7: 1644 | O7: 0 | P7: 1609 | Q7: 35 | R7: 820 | S7: 0 | T7: 0 | U7: 0 | V7: -0.636 | W7: 819.4 | X7: 230.4 | Y7: 0 | Z7: 588.9
A8: Selling General and Administrative | B8: 4021 | C8: 3762 | D8: 3397 | E8: 2757 | F8: 2225 | G8: 1609 | H8: 1334 | J8: 2020 02-02 | K8: 3979 | L8: 1756 | M8: 2223 | N8: 1334 | O8: 0 | P8: 1334 | Q8: 0.029 | R8: 889.1 | S8: 0 | T8: 0 | U8: 0 | V8: 8.28 | W8: 897.4 | X8: 251.8 | Y8: 0 | Z8: 645.6
A9: Other Operating Expenses | B9: -2.05 | C9: 2.73 | D9: 79.51 | E9: 406.5 | F9: 50.18 | G9: 35 | H9: 0.029
A10: Operating Income | B10: 2449 | C10: 2506 | D10: 2133 | E10: 1328 | F10: 1333 | G10: 820 | H10: 889.1
A11: Net Non-Operating Interest | B11: 0 | C11: 0 | D11: 0 | E11: 0 | F11: 0 | G11: 0 | H11: 0
A12: Interest Income | B12: 0 | C12: 0 | D12: 0 | E12: 0 | F12: 0 | G12: 0 | H12: 0
A13: Interest Expense | B13: 0 | C13: 0 | D13: 0 | E13: 0 | F13: 0 | G13: 0 | H13: 0
A14: Equity & Other Income/(Expense) | B14: 33.93 | C14: 70.38 | D14: 43.06 | E14: 4.16 | F14: 0.514 | G14: -0.636 | H14: 8.28
A15: Income Before Tax | B15: 2483 | C15: 2576 | D15: 2176 | E15: 1333 | F15: 1334 | G15: 819.4 | H15: 897.4
A16: Income Tax Expense | B16: 742.5 | C16: 761.5 | D16: 625.5 | E16: 477.8 | F16: 358.5 | G16: 230.4 | H16: 251.8
A17: Income Attributable to Non-Controlling Interest | B17: 0 | C17: 0 | D17: 0 | E17: 0 | F17: 0 | G17: 0 | H17: 0
A18: Net Income | B18: 1741 | C18: 1815 | D18: 1550 | E18: 854.8 | F18: 975.3 | G18: 588.9 | H18: 645.6
A19: Depreciation and Amortization | B19: 495.3 | C19: 446.5 | D19: 379.4 | E19: 291.8 | F19: 224.2 | G19: 185.5 | H19: 161.9
A20: EBITDA | B20: 2945 | C20: 2952 | D20: 2512 | E20: 1620 | F20: 1558 | G20: 1005 | H20: 1051
A21: Earnings Per Share (EPS) | B21: 14.45 | C21: 14.67 | D21: 12.23 | E21: 6.7 | F21: 7.52 | G21: 4.52 | H21: 4.95
A22: Diluted Earnings Per Share | B22: 14.43 | C22: 14.64 | D22: 12.2 | E22: 6.68 | F22: 7.49 | G22: 4.5 | H22: 4.93
A23: Weighted Average Shares Outstanding | B23: 118.5 | C23: 123.7 | D23: 126.7 | E23: 127.7 | F23: 129.8 | G23: 130.3 | H23: 130.4
A24: Diluted Weighted Average Shares Outstanding | B24: 118.6 | C24: 123.9 | D24: 127.1 | E24: 128 | F24: 130.3 | G24: 130.9 | H24: 131

Sheet Benchmarks analysis
A1: LuluLemon | B1: Operating Income | C1: Revenue | D1: Operating Margin
A2: 2021 | B2: =Lulu!R7 -> 820 | C2: =Lulu!K7 -> 4402 | D2: =B2/C2 -> 0.18627896
A3: 2022 | B3: =Lulu!R6 -> 1333 | C3: =Lulu!K6 -> 6257 | D3: =B3/C3 -> 0.21304139
A4: 2023 | B4: =Lulu!R5 -> 1328 | C4: =Lulu!K5 -> 8111 | D4: =B4/C4 -> 0.16372827
A5: 2024 | B5: =Lulu!R4 -> 2133 | C5: =Lulu!K4 -> 9619 | D5: =B5/C5 -> 0.22174862
A6: 2025 | B6: =Lulu!R3 -> 2506 | C6: =Lulu!K3 -> 10588 | D6: =B6/C6 -> 0.23668304
A8: Adidas EUR
A9: 2021 | B9: =ADDYY!J32 -> 1986 | C9: =ADDYY!C32 -> 21234 | D9: =B9/C9 -> 0.093529246
A10: 2022 | B10: =ADDYY!J31 -> 669 | C10: =ADDYY!C31 -> 22511 | D10: =B10/C10 -> 0.029718804
A11: 2023 | B11: =ADDYY!J30 -> 268 | C11: =ADDYY!C30 -> 21427 | D11: =B11/C11 -> 0.012507584
A12: 2024 | B12: =ADDYY!J29 -> 1337 | C12: =ADDYY!C29 -> 23683 | D12: =B12/C12 -> 0.056453997
A13: 2025 | B13: =ADDYY!J28 -> 1949 | C13: =ADDYY!C28 -> 2470 | D13: =B13/C13 -> 0.78906883
A15: Anta CYN
A16: 2021 | B16: =Anta!R6 -> 10.989 | C16: =Anta!K6 -> 49.328 | D16: =B16/C16 -> 0.22277408
A17: 2022 | B17: =Anta!R5 -> 11.23 | C17: =Anta!K5 -> 53.651 | D17: =B17/C17 -> 0.20931576
A18: 2023 | B18: =Anta!R4 -> 15.367 | C18: =Anta!K4 -> 62.356 | D18: =B18/C18 -> 0.2464398
A19: 2024 | B19: =Anta!R3 -> 16.595 | C19: =Anta!K3 -> 70.826 | D19: =B19/C19 -> 0.23430661
A20: 2025 | B20: =Anta!R2 -> 18.066 | C20: =Anta!K2 -> 75.635 | D20: =B20/C20 -> 0.23885767

Sheet Variance long
A1: Year | B1: Label | C1: Amount
A2: 2025 | B2: Prior Year NI (USD Billions) △ | C2: =Table8[[#This Row],[Prior Year NI (USD Billions) △]] -> 5.7
A3: 2025 | B3: Rev Change (USD Billions) △ | C3: ='WATERFALL Analysis'!C2 -> -5.053
A4: 2025 | B4: COGS Efficiency △ | C4: ='WATERFALL Analysis'!D2 -> -1.956
A5: 2025 | B5: OpEx Efficiency △ | C5: ='WATERFALL Analysis'!E2 -> -0.488
A6: 2025 | B6: Impact on Current NI (USD Billions) △ | C6: ='WATERFALL Analysis'!F2 -> 3.219
A7: 2024 | B7: Prior Year NI (USD Billions) △ | C7: ='WATERFALL Analysis'!B3 -> 5.07
A8: 2024 | B8: Rev Change (USD Billions) △ | C8: ='WATERFALL Analysis'!C3 -> 0.145
A9: 2024 | B9: COGS Efficiency △ | C9: ='WATERFALL Analysis'!D3 -> -0.45
A10: 2024 | B10: OpEx Efficiency △ | C10: ='WATERFALL Analysis'!E3 -> 0.199
A11: 2024 | B11: Impact on Current NI (USD Billions) △ | C11: ='WATERFALL Analysis'!F3 -> 5.7
A12: 2023 | B12: Prior Year NI (USD Billions) △ | C12: ='WATERFALL Analysis'!B4 -> 6.046
A13: 2023 | B13: Rev Change (USD Billions) △ | C13: ='WATERFALL Analysis'!C4 -> 4.507
A14: 2023 | B14: COGS Efficiency △ | C14: ='WATERFALL Analysis'!D4 -> 3.694
A15: 2023 | B15: OpEx Efficiency △ | C15: ='WATERFALL Analysis'!E4 -> 1.573
A16: 2023 | B16: Impact on Current NI (USD Billions) △ | C16: ='WATERFALL Analysis'!F4 -> 5.07
A17: 2022 | B17: Prior Year NI (USD Billions) △ | C17: ='WATERFALL Analysis'!B5 -> 5.727
A18: 2022 | B18: Rev Change (USD Billions) △ | C18: ='WATERFALL Analysis'!C5 -> 2.172
A19: 2022 | B19: COGS Efficiency △ | C19: ='WATERFALL Analysis'!D5 -> 0.655
A20: 2022 | B20: OpEx Efficiency △ | C20: ='WATERFALL Analysis'!E5 -> 1.779
A21: 2022 | B21: Impact on Current NI (USD Billions) △ | C21: ='WATERFALL Analysis'!F5 -> 6.046
A22: 2021 | B22: Prior Year NI (USD Billions) △ | C22: ='WATERFALL Analysis'!B6 -> 2.539
A23: 2021 | B23: Rev Change (USD Billions) △ | C23: ='WATERFALL Analysis'!C6 -> 7.135
A24: 2021 | B24: COGS Efficiency △ | C24: ='WATERFALL Analysis'!D6 -> 3.414
A25: 2021 | B25: OpEx Efficiency △ | C25: ='WATERFALL Analysis'!E6 -> -0.101
A26: 2021 | B26: Impact on Current NI (USD Billions) △ | C26: ='WATERFALL Analysis'!F6 -> 5.727

Sheet REC COMMENTS RAW
A1: Year | B1: Metric | C1: Amount
A2: 2025 | B2: Revenue Growth | C2: =Table5[[#This Row],[YoY %]] -> -0.098380125
A3: 2025 | B3: Net Income Margin | C3: ='Ratio Analysis'!G2 -> 0.069511326
A4: 2025 | B4: Operating expense ratio | C4: ='Ratio Analysis'!H2 -> 0.34740547
A5: 2025 | B5: Gross margin percentage | C5: ='IS ANALYSIS'!X2 -> 0.42734674
A6: 2025 | B6: Earnings Bridge Driver | C6: =MAX(ABS('VARIANCE ANALYSIS'!C2), ABS('VARIANCE ANALYSIS'!F2), ABS('WATERFALL Analysis'!D2)) -> 5.053
A7: 2024 | B7: Revenue Growth | C7: ='VARIANCE ANALYSIS'!D3 -> 0.0028310912
A8: 2024 | B8: Net Income Margin | C8: ='Ratio Analysis'!G3 -> 0.11097699
A9: 2024 | B9: Operating expense ratio | C9: ='Ratio Analysis'!H3 -> 0.32272887
A10: 2024 | B10: Gross margin percentage | C10: ='IS ANALYSIS'!X3 -> 0.44560181 | F10: Helper cells | G10: Value
A11: 2024 | B11: Earnings Bridge Driver | C11: =MAX(ABS('WATERFALL Analysis'!C3),ABS('WATERFALL Analysis'!D3),ABS('WATERFALL Analysis'!E3)) -> 0.45 | F11: Revenue Growth | G11: =GETPIVOTDATA("Amount",'Insights Pivot'!$A$3,"Metric","Revenue Growth") -> 0.096488975
A12: 2023 | B12: Revenue Growth | C12: ='VARIANCE ANALYSIS'!D4 -> 0.096488975 | F12: Net Income Margin | G12: =GETPIVOTDATA("Amount",'Insights Pivot'!$A$3,"Metric","Net Income Margin") -> -0.16142904
A13: 2023 | B13: Net Income Margin | C13: ='VARIANCE ANALYSIS'!P4 -> -0.16142904 | F13: Operating Expense | G13: =GETPIVOTDATA("Amount",'Insights Pivot'!$A$3,"Metric","Operating expense ratio") -> 0.31975711
A14: 2023 | B14: Operating expense ratio | C14: ='Ratio Analysis'!H4 -> 0.31975711 | F14: Gross Margin % | G14: =GETPIVOTDATA("Amount",'Insights Pivot'!$A$3,"Metric","Gross margin percentage") -> 0.43524611
A15: 2023 | B15: Gross margin percentage | C15: ='IS ANALYSIS'!X4 -> 0.43524611 | F15: Earnings Bridge | G15: =GETPIVOTDATA("Amount",'Insights Pivot'!$A$3,"Metric","Earnings Bridge Driver") -> 4.507
A16: 2023 | B16: Earnings Bridge Driver | C16: =MAX(ABS('WATERFALL Analysis'!C4), ABS('WATERFALL Analysis'!D4), ABS('WATERFALL Analysis'!E4)) -> 4.507
A17: 2022 | B17: Revenue Growth | C17: ='VARIANCE ANALYSIS'!D5 -> 0.048767345 | E17: Rev | F17: =IF(G11>0, "Revenue increased year-on-year, indicating topline growth.", "Revenue declined year-on-year, reflecting topline pressure.") -> Revenue increased year-on-year, indicating topline growth.
